[2023-06-27T07:58:19.810+0000] {taskinstance.py:1090} INFO - Dependencies all met for dep_context=non-requeueable deps ti=<TaskInstance: yolov5_ml_pipeline.generate_train_images manual__2023-06-27T07:57:31.055792+00:00 [queued]>
[2023-06-27T07:58:19.823+0000] {taskinstance.py:1090} INFO - Dependencies all met for dep_context=requeueable deps ti=<TaskInstance: yolov5_ml_pipeline.generate_train_images manual__2023-06-27T07:57:31.055792+00:00 [queued]>
[2023-06-27T07:58:19.823+0000] {taskinstance.py:1288} INFO - 
--------------------------------------------------------------------------------
[2023-06-27T07:58:19.824+0000] {taskinstance.py:1289} INFO - Starting attempt 1 of 1
[2023-06-27T07:58:19.824+0000] {taskinstance.py:1290} INFO - 
--------------------------------------------------------------------------------
[2023-06-27T07:58:19.844+0000] {taskinstance.py:1309} INFO - Executing <Task(KubernetesPodOperator): generate_train_images> on 2023-06-27 07:57:31.055792+00:00
[2023-06-27T07:58:19.847+0000] {standard_task_runner.py:55} INFO - Started process 106 to run task
[2023-06-27T07:58:19.850+0000] {standard_task_runner.py:82} INFO - Running: ['***', 'tasks', 'run', 'yolov5_ml_pipeline', 'generate_train_images', 'manual__2023-06-27T07:57:31.055792+00:00', '--job-id', '243', '--raw', '--subdir', 'DAGS_FOLDER/yolov5_pipe.py', '--cfg-path', '/tmp/tmp1nmc_iot']
[2023-06-27T07:58:19.852+0000] {standard_task_runner.py:83} INFO - Job 243: Subtask generate_train_images
[2023-06-27T07:58:20.476+0000] {task_command.py:389} INFO - Running <TaskInstance: yolov5_ml_pipeline.generate_train_images manual__2023-06-27T07:57:31.055792+00:00 [running]> on host yolov5-ml-pipeline-generate-tr-79affed9312149e1a4c1f655c3d806f7
[2023-06-27T07:58:21.389+0000] {logging_mixin.py:137} WARNING - /home/***/.local/lib/python3.8/site-packages/***/kubernetes/kube_config.py:58 DeprecationWarning: The namespace option in [kubernetes] has been moved to the namespace option in [kubernetes_executor] - the old setting has been used, but please update your config.
[2023-06-27T07:58:21.391+0000] {logging_mixin.py:137} WARNING - /home/***/.local/lib/python3.8/site-packages/***/kubernetes/kube_config.py:64 DeprecationWarning: The namespace option in [kubernetes] has been moved to the namespace option in [kubernetes_executor] - the old setting has been used, but please update your config.
[2023-06-27T07:58:21.392+0000] {pod_generator.py:424} WARNING - Model file /opt/***/pod_templates/pod_template.yaml does not exist
[2023-06-27T07:58:21.442+0000] {taskinstance.py:1516} INFO - Exporting the following env vars:
AIRFLOW_CTX_DAG_OWNER=***
AIRFLOW_CTX_DAG_ID=yolov5_ml_pipeline
AIRFLOW_CTX_TASK_ID=generate_train_images
AIRFLOW_CTX_EXECUTION_DATE=2023-06-27T07:57:31.055792+00:00
AIRFLOW_CTX_TRY_NUMBER=1
AIRFLOW_CTX_DAG_RUN_ID=manual__2023-06-27T07:57:31.055792+00:00
[2023-06-27T07:58:21.445+0000] {kubernetes_pod.py:815} INFO - Building pod generate-train-images-9hu2l8pw with labels: {'dag_id': 'yolov5_ml_pipeline', 'task_id': 'generate_train_images', 'run_id': 'manual__2023-06-27T075731.0557920000-5d196e870', 'kubernetes_pod_operator': 'True', 'try_number': '1'}
[2023-06-27T07:58:21.458+0000] {kubernetes_pod.py:870} ERROR - 'NoneType' object has no attribute 'metadata'
Traceback (most recent call last):
  File "/home/airflow/.local/lib/python3.8/site-packages/airflow/providers/cncf/kubernetes/operators/kubernetes_pod.py", line 521, in execute_sync
    self.pod = self.get_or_create_pod(  # must set `self.pod` for `on_kill`
  File "/home/airflow/.local/lib/python3.8/site-packages/airflow/providers/cncf/kubernetes/operators/kubernetes_pod.py", line 483, in get_or_create_pod
    pod = self.find_pod(self.namespace or pod_request_obj.metadata.namespace, context=context)
  File "/home/airflow/.local/lib/python3.8/site-packages/airflow/providers/cncf/kubernetes/operators/kubernetes_pod.py", line 465, in find_pod
    pod_list = self.client.list_namespaced_pod(
  File "/home/airflow/.local/lib/python3.8/site-packages/kubernetes/client/api/core_v1_api.py", line 15697, in list_namespaced_pod
    return self.list_namespaced_pod_with_http_info(namespace, **kwargs)  # noqa: E501
  File "/home/airflow/.local/lib/python3.8/site-packages/kubernetes/client/api/core_v1_api.py", line 15812, in list_namespaced_pod_with_http_info
    return self.api_client.call_api(
  File "/home/airflow/.local/lib/python3.8/site-packages/kubernetes/client/api_client.py", line 348, in call_api
    return self.__call_api(resource_path, method,
  File "/home/airflow/.local/lib/python3.8/site-packages/kubernetes/client/api_client.py", line 180, in __call_api
    response_data = self.request(
  File "/home/airflow/.local/lib/python3.8/site-packages/kubernetes/client/api_client.py", line 373, in request
    return self.rest_client.GET(url,
  File "/home/airflow/.local/lib/python3.8/site-packages/kubernetes/client/rest.py", line 240, in GET
    return self.request("GET", url,
  File "/home/airflow/.local/lib/python3.8/site-packages/kubernetes/client/rest.py", line 234, in request
    raise ApiException(http_resp=r)
kubernetes.client.exceptions.ApiException: (403)
Reason: Forbidden
HTTP response headers: HTTPHeaderDict({'Audit-Id': '1f9bbf56-e297-4cf5-8ed1-39a3619b644d', 'Cache-Control': 'no-cache, private', 'Content-Type': 'application/json', 'X-Content-Type-Options': 'nosniff', 'X-Kubernetes-Pf-Flowschema-Uid': '2ffa0171-8931-48d9-9da8-0078982a3504', 'X-Kubernetes-Pf-Prioritylevel-Uid': '7c274def-b891-453b-ba9b-67a9fe3902e1', 'Date': 'Tue, 27 Jun 2023 07:58:21 GMT', 'Content-Length': '297'})
HTTP response body: {"kind":"Status","apiVersion":"v1","metadata":{},"status":"Failure","message":"pods is forbidden: User \"system:serviceaccount:airflow-cluster:airflow-stable\" cannot list resource \"pods\" in API group \"\" in the namespace \"default\"","reason":"Forbidden","details":{"kind":"pods"},"code":403}



During handling of the above exception, another exception occurred:

Traceback (most recent call last):
  File "/home/airflow/.local/lib/python3.8/site-packages/airflow/providers/cncf/kubernetes/operators/kubernetes_pod.py", line 713, in patch_already_checked
    name=pod.metadata.name,
AttributeError: 'NoneType' object has no attribute 'metadata'
[2023-06-27T07:58:21.473+0000] {taskinstance.py:1776} ERROR - Task failed with exception
Traceback (most recent call last):
  File "/home/airflow/.local/lib/python3.8/site-packages/airflow/providers/cncf/kubernetes/operators/kubernetes_pod.py", line 521, in execute_sync
    self.pod = self.get_or_create_pod(  # must set `self.pod` for `on_kill`
  File "/home/airflow/.local/lib/python3.8/site-packages/airflow/providers/cncf/kubernetes/operators/kubernetes_pod.py", line 483, in get_or_create_pod
    pod = self.find_pod(self.namespace or pod_request_obj.metadata.namespace, context=context)
  File "/home/airflow/.local/lib/python3.8/site-packages/airflow/providers/cncf/kubernetes/operators/kubernetes_pod.py", line 465, in find_pod
    pod_list = self.client.list_namespaced_pod(
  File "/home/airflow/.local/lib/python3.8/site-packages/kubernetes/client/api/core_v1_api.py", line 15697, in list_namespaced_pod
    return self.list_namespaced_pod_with_http_info(namespace, **kwargs)  # noqa: E501
  File "/home/airflow/.local/lib/python3.8/site-packages/kubernetes/client/api/core_v1_api.py", line 15812, in list_namespaced_pod_with_http_info
    return self.api_client.call_api(
  File "/home/airflow/.local/lib/python3.8/site-packages/kubernetes/client/api_client.py", line 348, in call_api
    return self.__call_api(resource_path, method,
  File "/home/airflow/.local/lib/python3.8/site-packages/kubernetes/client/api_client.py", line 180, in __call_api
    response_data = self.request(
  File "/home/airflow/.local/lib/python3.8/site-packages/kubernetes/client/api_client.py", line 373, in request
    return self.rest_client.GET(url,
  File "/home/airflow/.local/lib/python3.8/site-packages/kubernetes/client/rest.py", line 240, in GET
    return self.request("GET", url,
  File "/home/airflow/.local/lib/python3.8/site-packages/kubernetes/client/rest.py", line 234, in request
    raise ApiException(http_resp=r)
kubernetes.client.exceptions.ApiException: (403)
Reason: Forbidden
HTTP response headers: HTTPHeaderDict({'Audit-Id': '1f9bbf56-e297-4cf5-8ed1-39a3619b644d', 'Cache-Control': 'no-cache, private', 'Content-Type': 'application/json', 'X-Content-Type-Options': 'nosniff', 'X-Kubernetes-Pf-Flowschema-Uid': '2ffa0171-8931-48d9-9da8-0078982a3504', 'X-Kubernetes-Pf-Prioritylevel-Uid': '7c274def-b891-453b-ba9b-67a9fe3902e1', 'Date': 'Tue, 27 Jun 2023 07:58:21 GMT', 'Content-Length': '297'})
HTTP response body: {"kind":"Status","apiVersion":"v1","metadata":{},"status":"Failure","message":"pods is forbidden: User \"system:serviceaccount:airflow-cluster:airflow-stable\" cannot list resource \"pods\" in API group \"\" in the namespace \"default\"","reason":"Forbidden","details":{"kind":"pods"},"code":403}



During handling of the above exception, another exception occurred:

Traceback (most recent call last):
  File "/home/airflow/.local/lib/python3.8/site-packages/airflow/providers/cncf/kubernetes/operators/kubernetes_pod.py", line 516, in execute
    return self.execute_sync(context)
  File "/home/airflow/.local/lib/python3.8/site-packages/airflow/providers/cncf/kubernetes/operators/kubernetes_pod.py", line 545, in execute_sync
    self.cleanup(
  File "/home/airflow/.local/lib/python3.8/site-packages/airflow/providers/cncf/kubernetes/operators/kubernetes_pod.py", line 671, in cleanup
    raise AirflowException(
airflow.exceptions.AirflowException: Pod generate-train-images-9hu2l8pw returned a failure:

remote_pod: None
[2023-06-27T07:58:21.475+0000] {taskinstance.py:1327} INFO - Marking task as FAILED. dag_id=yolov5_ml_pipeline, task_id=generate_train_images, execution_date=20230627T075731, start_date=20230627T075819, end_date=20230627T075821
[2023-06-27T07:58:21.486+0000] {standard_task_runner.py:100} ERROR - Failed to execute job 243 for task generate_train_images (Pod generate-train-images-9hu2l8pw returned a failure:

remote_pod: None; 106)
[2023-06-27T07:58:21.505+0000] {local_task_job.py:212} INFO - Task exited with return code 1
[2023-06-27T07:58:21.520+0000] {taskinstance.py:2596} INFO - 0 downstream tasks scheduled from follow-on schedule check
